<mujoco model="camera">
  <worldbody>
    <body name="head" pos="0.0076103 -0.01 1.02" euler="0 0 90">
      <joint name="slider_joint" pos="0 0 0" axis="0 0 -1" type="hinge" damping="0.04" />
	  <geom type="sphere" size=".01" rgba="0 0 0 0"  contype="0" conaffinity="0" />
	  <camera name="aorta_camera" pos="0 -0.8 0" euler="90 0 0" />
    </body>
  </worldbody>
  <actuator>
    <motor name="slider_motor" joint="slider_joint" ctrlrange="-1 1" ctrllimited="true" forcerange="-0.1 0.1" forcelimited="true" />
  </actuator>
</mujoco>
